<?xml version="1.0" ?>
<!-- =================================================================================== -->
<!-- |    This document was autogenerated by xacro from nao_robot_v3.urdf.xacro        | -->
<!-- |    EDITING THIS FILE BY HAND IS NOT RECOMMENDED                                 | -->
<!-- =================================================================================== -->
<robot name="nao" xmlns:xacro="http://ros.org/wiki/xacro">
  <!-- 
  ROS urdf definition of the Nao humanoid robot by Aldebaran Robotics

  This is part of the Nao-Stack of University of Freiburg, available at:
  http://code.google.com/p/alufr-ros-pkg/

  Authors: Armin Hornung, Stefan Osswald

  Joint names and properties are according to the Nao-documentation of
  Aldebaran Robotics ("Kinematics 3.2" for Nao V3.2). 
      
  Note that according to the documentation, the joint limits for the left leg 
  are different from the corresponding limits for the right leg. 
  For {L,R}HipPitch, {L,R}KneePitch and {L,R}AnklePitch the smallest interval 
  of the joint limits was chosen, whereas for {L,R}HipRoll and {L,R}AnkleRoll 
  the respective (differing) limits were copied from the documentation.
      
  The joint limits for {L,R}ShoulderRoll and {L,R}ElbowRoll do
  not include the zero position.
  
  This file loads a basic visualization of Nao and the structure (you need both)

-->
  <material name="LightGrey">
    <color rgba="0.8 0.8 0.8 1.0"/>
  </material>
  <material name="Grey">
    <color rgba="0.6 0.6 0.6 1.0"/>
  </material>
  <material name="DarkGrey">
    <color rgba="0.3 0.3 0.3 1.0"/>
  </material>
  <material name="Black">
    <color rgba="0.1 0.1 0.1 1.0"/>
  </material>
  <!-- 
  ROS urdf definition of the Nao humanoid robot by Aldebaran Robotics
  
  DO NOT INCLUDE THIS FILE DIRECTLY! USE nao_robot.urdf.xacro INSTEAD!

  This is part of the Nao-Stack of University of Freiburg, available at:
  http://code.google.com/p/alufr-ros-pkg/

  Authors: Armin Hornung, Stefan Osswald

  Joint names and properties are according to the Nao-documentation of
  Aldebaran Robotics ("Kinematics 3.2" for Nao V3.2) and REP-120:
  http://ros.org/reps/rep-0120.html
      
  Note that according to the documentation, the joint limits for the left leg 
  are different from the corresponding limits for the right leg. 
  For {L,R}HipPitch, {L,R}KneePitch and {L,R}AnklePitch the smallest interval 
  of the joint limits was chosen, whereas for {L,R}HipRoll and {L,R}AnkleRoll 
  the respective (differing) limits were copied from the documentation.
      
  The joint limits for {L,R}ShoulderRoll and {L,R}ElbowRoll do
  not include the zero position.

  TODO: effort and velocity limits are DUMMY values!
  TODO: Inertial matrix is wrong or contains dummdy values. 
        Docs say inertial matrix is in link frame, URDF expects CoM frame
-->
  <!-- dummy first link, directly connects with torso -->
  <link name="base_link"/>
  <!-- first real link of the robot, inertial reference frame -->
  <link name="torso">
    <!--<inertial>
      <origin xyz="0 0 0" rpy="0 0 0"/>
      <mass value="0"/>
      <inertia ixx="0"  ixy="0"  ixz="0" iyy="0" iyz="0" izz="0" />
    </inertial> -->
    <inertial>
      <origin rpy="0 0 0" xyz="-0.00480 0.00006 0.04227"/>
      <mass value="1.02628"/>
      <inertia ixx="0.00487953284" ixy="-0.00001428591" ixz="-0.00019545651" iyy="0.00470360698" iyz="0.00002224589" izz="0.0015671352"/>
    </inertial>
    <visual>
      <!-- one cylinder spanning over HipOffsetZ and NeckOffsetZ -->
      <origin rpy="0 0 0" xyz="0 0 0.02075"/>
      <geometry>
        <cylinder length="0.2115" radius="0.015"/>
      </geometry>
      <material name="LightGrey"/>
    </visual>
  </link>
  <link name="HeadYaw_link">
    <inertial>
      <origin rpy="0 0 0" xyz="-0.00003 0.00018 -0.02573"/>
      <mass value="0.05959"/>
      <inertia ixx="0.00006223368" ixy="0.00000000042" ixz="0.00000007448" iyy="0.00006324431" iyz="0.00000010416" izz="0.00000549462"/>
    </inertial>
  </link>
  <link name="HeadPitch_link">
    <inertial>
      <origin rpy="0 0 0" xyz="0.00383 -0.00093 0.05156"/>
      <mass value="0.47671"/>
      <inertia ixx="0.00208895741" ixy="0.00000549094" ixz="0.0001133995" iyy="1932222.63e-9" iyz="-0.00002803917" izz="0.00082257793"/>
    </inertial>
    <visual>
      <origin rpy="1.57 0 0" xyz="0 0 0.058"/>
      <geometry>
        <cylinder length="0.14" radius="0.04"/>
      </geometry>
      <material name="LightGrey"/>
    </visual>
  </link>
  <link name="gaze"/>
  <link name="CameraTop_frame">
  </link>
  <link name="CameraBottom_frame">
  </link>
  <!-- Arm -->
  <link name="l_wrist"/>
  <link name="r_wrist"/>
  <link name="l_gripper">
  </link>
  <link name="r_gripper">
  </link>
  <link name="LShoulderPitch_link">
    <inertial>
      <origin rpy="0 0 0" xyz="-0.00178 -0.02507 0.00019"/>
      <mass value="0.06984"/>
      <inertia ixx="0" ixy="0" ixz="0" iyy="0" iyz="0" izz="0"/>
    </inertial>
  </link>
  <link name="LShoulderRoll_link">
    <inertial>
      <origin rpy="0 0 0" xyz="0.02067 0.00388 0.00362"/>
      <mass value="0.12166"/>
      <inertia ixx="0" ixy="0" ixz="0" iyy="0" iyz="0" izz="0"/>
    </inertial>
    <visual>
      <origin rpy="1.57079632679 0 1.57079632679" xyz="0.045 0 0"/>
      <geometry>
        <cylinder length="0.09" radius="0.015"/>
      </geometry>
      <material name="LightGrey"/>
    </visual>
  </link>
  <link name="LElbowYaw_link">
    <inertial>
      <origin rpy="0 0 0" xyz="-0.02573 -1e-05 -0.00020"/>
      <mass value="0.05959"/>
      <inertia ixx="0" ixy="0" ixz="0" iyy="0" iyz="0" izz="0"/>
    </inertial>
  </link>
  <link name="LElbowRoll_link">
    <inertial>
      <origin rpy="0 0 0" xyz="0.01940 0.00304 0.00250"/>
      <mass value="0.03770"/>
      <inertia ixx="0" ixy="0" ixz="0" iyy="0" iyz="0" izz="0"/>
    </inertial>
    <visual>
      <origin rpy="1.57079632679 0 1.57079632679" xyz="0.025325 0 0"/>
      <geometry>
        <cylinder length="0.05065" radius="0.015"/>
      </geometry>
      <material name="LightGrey"/>
    </visual>
  </link>
  <link name="LWristYaw_link">
    <inertial>
      <origin rpy="0 0 0" xyz="0.03241 0.00268 -0.00272"/>
      <mass value="0.14314"/>
      <inertia ixx="0" ixy="0" ixz="0" iyy="0" iyz="0" izz="0"/>
    </inertial>
    <visual>
      <origin rpy="1.57079632679 0 1.57079632679" xyz="0.029 0 0"/>
      <geometry>
        <cylinder length="0.058" radius="0.015"/>
      </geometry>
      <material name="LightGrey"/>
    </visual>
  </link>
  <link name="RShoulderPitch_link">
    <inertial>
      <origin rpy="0 0 0" xyz="-0.00178 0.02507 0.00019"/>
      <mass value="0.06984"/>
      <inertia ixx="0" ixy="0" ixz="0" iyy="0" iyz="0" izz="0"/>
    </inertial>
  </link>
  <link name="RShoulderRoll_link">
    <inertial>
      <origin rpy="0 0 0" xyz="0.02067 -0.00388 0.00362"/>
      <mass value="0.12166"/>
      <inertia ixx="0" ixy="0" ixz="0" iyy="0" iyz="0" izz="0"/>
    </inertial>
    <visual>
      <origin rpy="1.57079632679 0 1.57079632679" xyz="0.045 0 0"/>
      <geometry>
        <cylinder length="0.09" radius="0.015"/>
      </geometry>
      <material name="LightGrey"/>
    </visual>
  </link>
  <link name="RElbowYaw_link">
    <inertial>
      <origin rpy="0 0 0" xyz="-0.02573 1e-05 -0.00020"/>
      <mass value="0.05959"/>
      <inertia ixx="0" ixy="0" ixz="0" iyy="0" iyz="0" izz="0"/>
    </inertial>
  </link>
  <link name="RElbowRoll_link">
    <inertial>
      <origin rpy="0 0 0" xyz="0.01940 -0.00304 0.00250"/>
      <mass value="0.03770"/>
      <inertia ixx="0" ixy="0" ixz="0" iyy="0" iyz="0" izz="0"/>
    </inertial>
    <visual>
      <origin rpy="1.57079632679 0 1.57079632679" xyz="0.025325 0 0"/>
      <geometry>
        <cylinder length="0.05065" radius="0.015"/>
      </geometry>
      <material name="LightGrey"/>
    </visual>
  </link>
  <link name="RWristYaw_link">
    <inertial>
      <origin rpy="0 0 0" xyz="0.03241 -0.00268 -0.00272"/>
      <mass value="0.14314"/>
      <inertia ixx="0" ixy="0" ixz="0" iyy="0" iyz="0" izz="0"/>
    </inertial>
    <visual>
      <origin rpy="1.57079632679 0 1.57079632679" xyz="0.029 0 0"/>
      <geometry>
        <cylinder length="0.058" radius="0.015"/>
      </geometry>
      <material name="LightGrey"/>
    </visual>
  </link>
  <!-- Leg links -->
  <link name="l_ankle"/>
  <link name="r_ankle"/>
  <link name="l_sole">
    <visual>
      <origin rpy="0 0 0" xyz="0.02 0 0.0075"/>
      <geometry>
        <box size="0.16 0.06 0.015"/>
      </geometry>
      <material name="LightGrey"/>
    </visual>
  </link>
  <link name="r_sole">
    <visual>
      <origin rpy="0 0 0" xyz="0.02 0 0.0075"/>
      <geometry>
        <box size="0.16 0.06 0.015"/>
      </geometry>
      <material name="LightGrey"/>
    </visual>
  </link>
  <link name="LHipYawPitch_link">
    <inertial>
      <origin rpy="0 0 0" xyz="-0.00717 -0.01187 0.02705"/>
      <mass value="0.07244"/>
      <inertia ixx="0" ixy="0" ixz="0" iyy="0" iyz="0" izz="0"/>
    </inertial>
  </link>
  <link name="LHipRoll_link">
    <inertial>
      <origin rpy="0 0 0" xyz="-0.01649 0.00029 -0.00475"/>
      <mass value="0.13530"/>
      <inertia ixx="0" ixy="0" ixz="0" iyy="0" iyz="0" izz="0"/>
    </inertial>
  </link>
  <link name="LHipPitch_link">
    <inertial>
      <origin rpy="0 0 0" xyz="0.00131 0.00201 -0.05386"/>
      <mass value="0.39798"/>
      <inertia ixx="0" ixy="0" ixz="0" iyy="0" iyz="0" izz="0"/>
    </inertial>
    <visual>
      <origin rpy="0 0 0" xyz="0 0 -0.05"/>
      <geometry>
        <cylinder length="0.1" radius="0.015"/>
      </geometry>
      <material name="LightGrey"/>
    </visual>
  </link>
  <link name="LKneePitch_link">
    <inertial>
      <origin rpy="0 0 0" xyz="0.00471 0.0021 -0.04891"/>
      <mass value="0.29706"/>
      <inertia ixx="0" ixy="0" ixz="0" iyy="0" iyz="0" izz="0"/>
    </inertial>
    <visual>
      <origin rpy="0 0 0" xyz="0 0 -0.05"/>
      <geometry>
        <cylinder length="0.1" radius="0.015"/>
      </geometry>
      <material name="LightGrey"/>
    </visual>
  </link>
  <link name="LAnklePitch_link">
    <inertial>
      <origin rpy="0 0 0" xyz="0.00142 0.00028 0.00638"/>
      <mass value="0.13892"/>
      <inertia ixx="0" ixy="0" ixz="0" iyy="0" iyz="0" izz="0"/>
    </inertial>
  </link>
  <link name="LAnkleRoll_link">
    <inertial>
      <origin rpy="0 0 0" xyz="0.02489 0.0033 -0.03208"/>
      <mass value="0.16304"/>
      <inertia ixx="0" ixy="0" ixz="0" iyy="0" iyz="0" izz="0"/>
    </inertial>
    <visual>
      <origin rpy="0 0 0" xyz="0 0 -0.023"/>
      <geometry>
        <cylinder length="0.046" radius="0.015"/>
      </geometry>
      <material name="LightGrey"/>
    </visual>
  </link>
  <link name="RHipYawPitch_link">
    <inertial>
      <origin rpy="0 0 0" xyz="-0.00717 0.01187 0.02705"/>
      <mass value="0.07244"/>
      <inertia ixx="0" ixy="0" ixz="0" iyy="0" iyz="0" izz="0"/>
    </inertial>
  </link>
  <link name="RHipRoll_link">
    <inertial>
      <origin rpy="0 0 0" xyz="-0.01649 -0.00029 -0.00475"/>
      <mass value="0.13530"/>
      <inertia ixx="0" ixy="0" ixz="0" iyy="0" iyz="0" izz="0"/>
    </inertial>
  </link>
  <link name="RHipPitch_link">
    <inertial>
      <origin rpy="0 0 0" xyz="0.00131 -0.00201 -0.05386"/>
      <mass value="0.39798"/>
      <inertia ixx="0" ixy="0" ixz="0" iyy="0" iyz="0" izz="0"/>
    </inertial>
    <visual>
      <origin rpy="0 0 0" xyz="0 0 -0.05"/>
      <geometry>
        <cylinder length="0.1" radius="0.015"/>
      </geometry>
      <material name="LightGrey"/>
    </visual>
  </link>
  <link name="RKneePitch_link">
    <inertial>
      <origin rpy="0 0 0" xyz="0.00471 -0.0021 -0.04891"/>
      <mass value="0.29706"/>
      <inertia ixx="0" ixy="0" ixz="0" iyy="0" iyz="0" izz="0"/>
    </inertial>
    <visual>
      <origin rpy="0 0 0" xyz="0 0 -0.05"/>
      <geometry>
        <cylinder length="0.1" radius="0.015"/>
      </geometry>
      <material name="LightGrey"/>
    </visual>
  </link>
  <link name="RAnklePitch_link">
    <inertial>
      <origin rpy="0 0 0" xyz="0.00142 -0.00028 0.00638"/>
      <mass value="0.13892"/>
      <inertia ixx="0" ixy="0" ixz="0" iyy="0" iyz="0" izz="0"/>
    </inertial>
  </link>
  <link name="RAnkleRoll_link">
    <inertial>
      <origin rpy="0 0 0" xyz="0.02489 -0.0033 -0.03208"/>
      <mass value="0.16304"/>
      <inertia ixx="0" ixy="0" ixz="0" iyy="0" iyz="0" izz="0"/>
    </inertial>
    <visual>
      <origin rpy="0 0 0" xyz="0 0 -0.023"/>
      <geometry>
        <cylinder length="0.046" radius="0.015"/>
      </geometry>
      <material name="LightGrey"/>
    </visual>
  </link>
  <!--   Joints following below -->
  <joint name="base_joint" type="fixed">
    <child link="torso"/>
    <parent link="base_link"/>
    <origin rpy="0 0 0" xyz="0 0 0"/>
  </joint>
  <!-- Head joints -->
  <joint name="HeadYaw" type="revolute">
    <parent link="torso"/>
    <child link="HeadYaw_link"/>
    <!-- NeckOffsetZ -->
    <origin rpy="0 0 0" xyz="0 0 0.1265"/>
    <axis xyz="0 0 1"/>
    <limit effort="30" lower="-2.0857" upper="2.0857" velocity="3.0"/>
  </joint>
  <joint name="HeadPitch" type="revolute">
    <parent link="HeadYaw_link"/>
    <child link="HeadPitch_link"/>
    <origin rpy="0 0 0" xyz="0 0 0"/>
    <axis xyz="0 1 0"/>
    <limit effort="30" lower="-0.6720" upper="0.5149" velocity="3.0"/>
  </joint>
  <joint name="gaze_joint" type="fixed">
    <parent link="HeadPitch_link"/>
    <child link="gaze"/>
    <origin xyz="0.0539 0 0.05"/>
  </joint>
  <joint name="CameraTop" type="fixed">
    <parent link="HeadPitch_link"/>
    <child link="CameraTop_frame"/>
    <origin rpy="-1.57079632679 0 -1.57079632679" xyz="0.0539 0 0.0679"/>
  </joint>
  <joint name="CameraBottom" type="fixed">
    <parent link="HeadPitch_link"/>
    <child link="CameraBottom_frame"/>
    <!-- rotated by 40 degrees (pitch) -->
    <origin rpy="-2.26893 0 -1.57079632679" xyz="0.0488 0 0.02381"/>
  </joint>
  <!-- Arm joints -->
  <joint name="l_wrist_joint" type="fixed">
    <parent link="LWristYaw_link"/>
    <child link="l_wrist"/>
    <origin xyz="0 0 0"/>
  </joint>
  <joint name="r_wrist_joint" type="fixed">
    <parent link="RWristYaw_link"/>
    <child link="r_wrist"/>
    <origin xyz="0 0 0"/>
  </joint>
  <joint name="l_gripper_joint" type="fixed">
    <parent link="l_wrist"/>
    <child link="l_gripper"/>
    <origin xyz="0.058 0 -0.0159"/>
  </joint>
  <joint name="r_gripper_joint" type="fixed">
    <parent link="r_wrist"/>
    <child link="r_gripper"/>
    <origin xyz="0.058 0 -0.0159"/>
  </joint>
  <joint name="LElbowRoll" type="revolute">
    <parent link="LElbowYaw_link"/>
    <child link="LElbowRoll_link"/>
    <origin rpy="0 0 0" xyz="0 0 0"/>
    <axis xyz="0 0 1"/>
    <limit effort="30" lower="-1.5621" upper="-0.0087" velocity="3.0"/>
  </joint>
  <joint name="RElbowRoll" type="revolute">
    <parent link="RElbowYaw_link"/>
    <child link="RElbowRoll_link"/>
    <origin rpy="0 0 0" xyz="0 0 0"/>
    <axis xyz="0 0 1"/>
    <limit effort="30" lower="0.0087" upper="1.5621" velocity="3.0"/>
  </joint>
  <joint name="LShoulderRoll" type="revolute">
    <parent link="LShoulderPitch_link"/>
    <child link="LShoulderRoll_link"/>
    <origin rpy="0 0 0" xyz="0 0 0"/>
    <axis xyz="0 0 1"/>
    <limit effort="30" lower="0.0087" upper="1.6494" velocity="3.0"/>
  </joint>
  <joint name="RShoulderRoll" type="revolute">
    <parent link="RShoulderPitch_link"/>
    <child link="RShoulderRoll_link"/>
    <origin rpy="0 0 0" xyz="0 0 0"/>
    <axis xyz="0 0 1"/>
    <limit effort="30" lower="-1.6494" upper="-0.0087" velocity="3.0"/>
  </joint>
  <joint name="LShoulderPitch" type="revolute">
    <parent link="torso"/>
    <child link="LShoulderPitch_link"/>
    <origin rpy="0 0 0" xyz="0 0.098 0.1"/>
    <axis xyz="0 1 0"/>
    <limit effort="30" lower="-2.0857" upper="2.0857" velocity="3.0"/>
  </joint>
  <joint name="LElbowYaw" type="revolute">
    <parent link="LShoulderRoll_link"/>
    <child link="LElbowYaw_link"/>
    <origin rpy="0 0 0" xyz="0.09 0 0"/>
    <axis xyz="1 0 0"/>
    <limit effort="30" lower="-2.0857" upper="2.0857" velocity="3.0"/>
  </joint>
  <joint name="LWristYaw" type="revolute">
    <parent link="LElbowRoll_link"/>
    <child link="LWristYaw_link"/>
    <origin rpy="0 0 0" xyz="0.05055 0 0"/>
    <axis xyz="1 0 0"/>
    <limit effort="30" lower="-1.8238" upper="1.8238" velocity="3.0"/>
  </joint>
  <joint name="RShoulderPitch" type="revolute">
    <parent link="torso"/>
    <child link="RShoulderPitch_link"/>
    <origin rpy="0 0 0" xyz="0 -0.098 0.1"/>
    <axis xyz="0 1 0"/>
    <limit effort="30" lower="-2.0857" upper="2.0857" velocity="3.0"/>
  </joint>
  <joint name="RElbowYaw" type="revolute">
    <parent link="RShoulderRoll_link"/>
    <child link="RElbowYaw_link"/>
    <origin rpy="0 0 0" xyz="0.09 0 0"/>
    <axis xyz="1 0 0"/>
    <limit effort="30" lower="-2.0857" upper="2.0857" velocity="3.0"/>
  </joint>
  <joint name="RWristYaw" type="revolute">
    <parent link="RElbowRoll_link"/>
    <child link="RWristYaw_link"/>
    <origin rpy="0 0 0" xyz="0.05055 0 0"/>
    <axis xyz="1 0 0"/>
    <limit effort="30" lower="-1.8238" upper="1.8238" velocity="3.0"/>
  </joint>
  <!-- Leg joints -->
  <joint name="LHipYawPitch" type="revolute">
    <parent link="torso"/>
    <child link="LHipYawPitch_link"/>
    <origin rpy="0 0 0" xyz="0 0.05 -0.085"/>
    <axis xyz="0 0.707106 -0.707106"/>
    <limit effort="30" lower="-1.145303" upper="0.740810" velocity="3.0"/>
  </joint>
  <joint name="RHipYawPitch" type="revolute">
    <parent link="torso"/>
    <child link="RHipYawPitch_link"/>
    <origin rpy="0 0 0" xyz="0 -0.05 -0.085"/>
    <axis xyz="0 0.707106 0.707106"/>
    <limit effort="30" lower="-1.145303" upper="0.740810" velocity="3.0"/>
    <mimic joint="LHipYawPitch" multiplier="1" offset="0"/>
  </joint>
  <joint name="LHipRoll" type="revolute">
    <parent link="LHipYawPitch_link"/>
    <child link="LHipRoll_link"/>
    <origin rpy="0 0 0" xyz="0 0 0"/>
    <axis xyz="1 0 0"/>
    <limit effort="30" lower="-0.379472" upper="0.790477" velocity="3.0"/>
  </joint>
  <joint name="RHipRoll" type="revolute">
    <parent link="RHipYawPitch_link"/>
    <child link="RHipRoll_link"/>
    <origin rpy="0 0 0" xyz="0 0 0"/>
    <axis xyz="1 0 0"/>
    <limit effort="30" lower="-0.738321" upper="0.414754" velocity="3.0"/>
  </joint>
  <joint name="LAnkleRoll" type="revolute">
    <parent link="LAnklePitch_link"/>
    <child link="LAnkleRoll_link"/>
    <origin rpy="0 0 0" xyz="0 0 0"/>
    <axis xyz="1 0 0"/>
    <limit effort="30" lower="-0.769001" upper="0.397880" velocity="3.0"/>
  </joint>
  <joint name="RAnkleRoll" type="revolute">
    <parent link="RAnklePitch_link"/>
    <child link="RAnkleRoll_link"/>
    <origin rpy="0 0 0" xyz="0 0 0"/>
    <axis xyz="1 0 0"/>
    <limit effort="30" lower="-0.388676" upper="0.785875" velocity="3.0"/>
  </joint>
  <joint name="l_ankle_joint" type="fixed">
    <parent link="LAnkleRoll_link"/>
    <child link="l_ankle"/>
    <origin xyz="0 0 0"/>
  </joint>
  <joint name="r_ankle_joint" type="fixed">
    <parent link="RAnkleRoll_link"/>
    <child link="r_ankle"/>
    <origin xyz="0 0 0"/>
  </joint>
  <joint name="l_sole_joint" type="fixed">
    <parent link="l_ankle"/>
    <child link="l_sole"/>
    <origin xyz="0 0 -0.04511"/>
  </joint>
  <joint name="r_sole_joint" type="fixed">
    <parent link="r_ankle"/>
    <child link="r_sole"/>
    <origin xyz="0 0 -0.04511"/>
  </joint>
  <joint name="LHipPitch" type="revolute">
    <parent link="LHipRoll_link"/>
    <child link="LHipPitch_link"/>
    <origin rpy="0 0 0" xyz="0 0 0"/>
    <axis xyz="0 1 0"/>
    <!-- LHipPitch limits: -1.773912 .. 0.484090 -->
    <!-- RHipPitch limits: -1.772308 .. 0.485624 -->
    <limit effort="30" lower="-1.772308" upper="0.484090" velocity="3.0"/>
  </joint>
  <joint name="LKneePitch" type="revolute">
    <parent link="LHipPitch_link"/>
    <child link="LKneePitch_link"/>
    <origin rpy="0 0 0" xyz="0 0 -0.1"/>
    <axis xyz="0 1 0"/>
    <!-- LKneePitch limits: -0.092346 .. 2.112528 -->
    <!-- RKneePitch limits: -0.103083 .. 2.120198 -->
    <limit effort="30" lower="-0.092346" upper="2.112528" velocity="3.0"/>
  </joint>
  <joint name="LAnklePitch" type="revolute">
    <parent link="LKneePitch_link"/>
    <child link="LAnklePitch_link"/>
    <origin rpy="0 0 0" xyz="0 0 -0.10275"/>
    <axis xyz="0 1 0"/>
    <!-- LAnklePitch limits: -1.189516 .. 0.922747 -->
    <!-- RAnklePitch limits: -1.186448 .. 0.932056 -->
    <limit effort="30" lower="-1.186448" upper="0.922747" velocity="3.0"/>
  </joint>
  <joint name="RHipPitch" type="revolute">
    <parent link="RHipRoll_link"/>
    <child link="RHipPitch_link"/>
    <origin rpy="0 0 0" xyz="0 0 0"/>
    <axis xyz="0 1 0"/>
    <!-- LHipPitch limits: -1.773912 .. 0.484090 -->
    <!-- RHipPitch limits: -1.772308 .. 0.485624 -->
    <limit effort="30" lower="-1.772308" upper="0.484090" velocity="3.0"/>
  </joint>
  <joint name="RKneePitch" type="revolute">
    <parent link="RHipPitch_link"/>
    <child link="RKneePitch_link"/>
    <origin rpy="0 0 0" xyz="0 0 -0.1"/>
    <axis xyz="0 1 0"/>
    <!-- LKneePitch limits: -0.092346 .. 2.112528 -->
    <!-- RKneePitch limits: -0.103083 .. 2.120198 -->
    <limit effort="30" lower="-0.092346" upper="2.112528" velocity="3.0"/>
  </joint>
  <joint name="RAnklePitch" type="revolute">
    <parent link="RKneePitch_link"/>
    <child link="RAnklePitch_link"/>
    <origin rpy="0 0 0" xyz="0 0 -0.10275"/>
    <axis xyz="0 1 0"/>
    <!-- LAnklePitch limits: -1.189516 .. 0.922747 -->
    <!-- RAnklePitch limits: -1.186448 .. 0.932056 -->
    <limit effort="30" lower="-1.186448" upper="0.922747" velocity="3.0"/>
  </joint>
</robot>

